<?xml version='1.0'?>
<sdf version='1.6'>
  <model name='FourBar'>
    <link name='base_link'>
      <pose frame=''>0 0 0 0 -0 0</pose>
      <inertial>
        <mass>1</mass>
        <inertia>
          <ixx>1</ixx>
          <ixy>0</ixy>
          <ixz>0</ixz>
          <iyy>1</iyy>
          <iyz>0</iyz>
          <izz>1</izz>
        </inertia>
      </inertial>
      <self_collide>0</self_collide>
      <kinematic>0</kinematic>
      <visual name='base'>
        <pose frame=''>0 0 0 0 -0 0</pose>
        <geometry>
          <cylinder>
            <length>4</length>
            <radius>0.2</radius>
          </cylinder>
        </geometry>
        <material>
          <diffuse>0.6353 0.6353 0.6353 1</diffuse>
          <ambient>1 1 1 1</ambient>
          <specular>0 0 0 1</specular>
          <emissive>0 0 0 1</emissive>
          <script>
            <name>ModelPreview_1::base_link::base_MATERIAL_</name>
            <uri>__default__</uri>
          </script>
        </material>
        <cast_shadows>1</cast_shadows>
        <transparency>0</transparency>
      </visual>
    </link>
    <link name='link_1'>
      <pose frame=''>0 0 0 0 -0 0</pose>
      <inertial>
        <mass>1</mass>
        <inertia>
          <ixx>1</ixx>
          <ixy>0</ixy>
          <ixz>0</ixz>
          <iyy>1</iyy>
          <iyz>0</iyz>
          <izz>1</izz>
        </inertia>
      </inertial>
      <self_collide>0</self_collide>
      <kinematic>0</kinematic>
      <visual name='link1'>
        <pose frame=''>0 0 0.9 0 -0 0</pose>
        <geometry>
          <cylinder>
            <length>1.8</length>
            <radius>0.2</radius>
          </cylinder>
        </geometry>
        <material>
          <diffuse>0.6353 0.6353 0.6353 1</diffuse>
          <ambient>1 1 1 1</ambient>
          <specular>0 0 0 1</specular>
          <emissive>0 0 0 1</emissive>
          <script>
            <name>ModelPreview_1::link_1::link1_MATERIAL_</name>
            <uri>__default__</uri>
          </script>
        </material>
        <cast_shadows>1</cast_shadows>
        <transparency>0</transparency>
      </visual>
    </link>
    <link name='link_2'>
      <pose frame=''>0 0 0 0 -0 0</pose>
      <inertial>
        <mass>1</mass>
        <inertia>
          <ixx>1</ixx>
          <ixy>0</ixy>
          <ixz>0</ixz>
          <iyy>1</iyy>
          <iyz>0</iyz>
          <izz>1</izz>
        </inertia>
      </inertial>
      <self_collide>0</self_collide>
      <kinematic>0</kinematic>
      <visual name='link2'>
        <pose frame=''>0 0 1.8 0 -0 0</pose>
        <geometry>
          <cylinder>
            <length>3.6</length>
            <radius>0.2</radius>
          </cylinder>
        </geometry>
        <material>
          <diffuse>0.6353 0.6353 0.6353 1</diffuse>
          <ambient>1 1 1 1</ambient>
          <specular>0 0 0 1</specular>
          <emissive>0 0 0 1</emissive>
          <script>
            <name>ModelPreview_1::link_2::link2_MATERIAL_</name>
            <uri>__default__</uri>
          </script>
        </material>
        <cast_shadows>1</cast_shadows>
        <transparency>0</transparency>
      </visual>
    </link>
    <link name='link_3'>
      <pose frame=''>0 0 0 0 -0 0</pose>
      <inertial>
        <mass>1</mass>
        <inertia>
          <ixx>1</ixx>
          <ixy>0</ixy>
          <ixz>0</ixz>
          <iyy>1</iyy>
          <iyz>0</iyz>
          <izz>1</izz>
        </inertia>
      </inertial>
      <self_collide>0</self_collide>
      <kinematic>0</kinematic>
      <visual name='link3'>
        <pose frame=''>0 0 1.3 0 -0 0</pose>
        <geometry>
          <cylinder>
            <length>2.6</length>
            <radius>0.2</radius>
          </cylinder>
        </geometry>
        <material>
          <diffuse>0.6353 0.6353 0.6353 1</diffuse>
          <ambient>1 1 1 1</ambient>
          <specular>0 0 0 1</specular>
          <emissive>0 0 0 1</emissive>
          <script>
            <name>ModelPreview_1::link_3::link3_MATERIAL_</name>
            <uri>__default__</uri>
          </script>
        </material>
        <cast_shadows>1</cast_shadows>
        <transparency>0</transparency>
      </visual>
    </link>
    <joint name='joint_0' type='revolute'>
      <parent>base_link</parent>
      <child>link_1</child>
      <pose frame=''>0 0 2 0 -0 0</pose>
      <axis>
        <xyz>0 1 0</xyz>
        <use_parent_model_frame>0</use_parent_model_frame>
        <limit>
          <lower>-1e+16</lower>
          <upper>1e+16</upper>
          <effort>-1</effort>
          <velocity>-1</velocity>
        </limit>
        <dynamics>
          <spring_reference>0</spring_reference>
          <spring_stiffness>0</spring_stiffness>
          <damping>0</damping>
          <friction>0</friction>
        </dynamics>
      </axis>
      <physics>
        <ode>
          <limit>
            <cfm>0</cfm>
            <erp>0.2</erp>
          </limit>
          <suspension>
            <cfm>0</cfm>
            <erp>0.2</erp>
          </suspension>
        </ode>
      </physics>
    </joint>
    <joint name='joint_1' type='revolute'>
      <parent>link_1</parent>
      <child>link_2</child>
      <pose frame=''>0 0 1.8 0 -0 0</pose>
      <axis>
        <xyz>0 1 0</xyz>
        <use_parent_model_frame>0</use_parent_model_frame>
        <limit>
          <lower>-1e+16</lower>
          <upper>1e+16</upper>
          <effort>100</effort>
          <velocity>-1</velocity>
        </limit>
        <dynamics>
          <spring_reference>0</spring_reference>
          <spring_stiffness>0</spring_stiffness>
          <damping>0</damping>
          <friction>0</friction>
        </dynamics>
      </axis>
      <physics>
        <ode>
          <limit>
            <cfm>0</cfm>
            <erp>0.2</erp>
          </limit>
          <suspension>
            <cfm>0</cfm>
            <erp>0.2</erp>
          </suspension>
        </ode>
      </physics>
    </joint>
    <joint name='joint_2' type='revolute'>
      <parent>link_2</parent>
      <child>link_3</child>
      <pose frame=''>0 0 3.6 0 -0 0</pose>
      <axis>
        <xyz>0 1 0</xyz>
        <use_parent_model_frame>0</use_parent_model_frame>
        <limit>
          <lower>-1e+16</lower>
          <upper>1e+16</upper>
          <effort>-1</effort>
          <velocity>-1</velocity>
        </limit>
        <dynamics>
          <spring_reference>0</spring_reference>
          <spring_stiffness>0</spring_stiffness>
          <damping>0</damping>
          <friction>0</friction>
        </dynamics>
      </axis>
      <physics>
        <ode>
          <limit>
            <cfm>0</cfm>
            <erp>0.2</erp>
          </limit>
          <suspension>
            <cfm>0</cfm>
            <erp>0.2</erp>
          </suspension>
        </ode>
      </physics>
    </joint>
    <joint name='joint_3' type='revolute'>
      <parent>base_link</parent>
      <child>link_3</child>
      <pose frame=''>0 0 2.6 0 -0 0</pose>
      <axis>
        <xyz>0 1 0</xyz>
        <use_parent_model_frame>0</use_parent_model_frame>
        <limit>
          <lower>-1e+16</lower>
          <upper>1e+16</upper>
          <effort>-1</effort>
          <velocity>-1</velocity>
        </limit>
        <dynamics>
          <spring_reference>0</spring_reference>
          <spring_stiffness>0</spring_stiffness>
          <damping>0</damping>
          <friction>0</friction>
        </dynamics>
      </axis>
      <physics>
        <ode>
          <limit>
            <cfm>0</cfm>
            <erp>0.2</erp>
          </limit>
          <suspension>
            <cfm>0</cfm>
            <erp>0.2</erp>
          </suspension>
        </ode>
      </physics>
    </joint>
    <static>0</static>
    <allow_auto_disable>1</allow_auto_disable>
  </model>
</sdf>
